============================= test session starts ==============================
platform linux -- Python 3.12.3, pytest-7.4.4, pluggy-1.5.0
rootdir: /home/kasper/Programming/mediaocean-cc/backend
plugins: Faker-37.4.2
collected 1 item

tests/test_summary.py F                                                  [100%]

=================================== FAILURES ===================================
____________________ TestSummaryFunctions.test_count_words _____________________

cls = <class '_pytest.runner.CallInfo'>
func = <function call_runtest_hook.<locals>.<lambda> at 0x7dea4fe99260>
when = 'call'
reraise = (<class '_pytest.outcomes.Exit'>, <class 'KeyboardInterrupt'>)

    @classmethod
    def from_call(
        cls,
        func: "Callable[[], TResult]",
        when: "Literal['collect', 'setup', 'call', 'teardown']",
        reraise: Optional[
            Union[Type[BaseException], Tuple[Type[BaseException], ...]]
        ] = None,
    ) -> "CallInfo[TResult]":
        """Call func, wrapping the result in a CallInfo.
    
        :param func:
            The function to call. Called without arguments.
        :param when:
            The phase in which the function is called.
        :param reraise:
            Exception or exceptions that shall propagate if raised by the
            function, instead of being wrapped in the CallInfo.
        """
        excinfo = None
        start = timing.time()
        precise_start = timing.perf_counter()
        try:
>           result: Optional[TResult] = func()

.venv/lib/python3.12/site-packages/_pytest/runner.py:341: 
_ _ _ _ _ _ _ _ _ _ _ _ _ _ _ _ _ _ _ _ _ _ _ _ _ _ _ _ _ _ _ _ _ _ _ _ _ _ _ _ 
.venv/lib/python3.12/site-packages/_pytest/runner.py:262: in <lambda>
    lambda: ihook(item=item, **kwds), when=when, reraise=reraise
.venv/lib/python3.12/site-packages/pluggy/_hooks.py:513: in __call__
    return self._hookexec(self.name, self._hookimpls.copy(), kwargs, firstresult)
.venv/lib/python3.12/site-packages/pluggy/_manager.py:120: in _hookexec
    return self._inner_hookexec(hook_name, methods, kwargs, firstresult)
.venv/lib/python3.12/site-packages/_pytest/runner.py:177: in pytest_runtest_call
    raise e
.venv/lib/python3.12/site-packages/_pytest/runner.py:169: in pytest_runtest_call
    item.runtest()
.venv/lib/python3.12/site-packages/_pytest/python.py:1792: in runtest
    self.ihook.pytest_pyfunc_call(pyfuncitem=self)
.venv/lib/python3.12/site-packages/pluggy/_hooks.py:513: in __call__
    return self._hookexec(self.name, self._hookimpls.copy(), kwargs, firstresult)
.venv/lib/python3.12/site-packages/pluggy/_manager.py:120: in _hookexec
    return self._inner_hookexec(hook_name, methods, kwargs, firstresult)
_ _ _ _ _ _ _ _ _ _ _ _ _ _ _ _ _ _ _ _ _ _ _ _ _ _ _ _ _ _ _ _ _ _ _ _ _ _ _ _ 

pyfuncitem = <Function test_count_words>

    @hookimpl(trylast=True)
    def pytest_pyfunc_call(pyfuncitem: "Function") -> Optional[object]:
        testfunction = pyfuncitem.obj
        if is_async_function(testfunction):
            async_warn_and_skip(pyfuncitem.nodeid)
        funcargs = pyfuncitem.funcargs
        testargs = {arg: funcargs[arg] for arg in pyfuncitem._fixtureinfo.argnames}
>       result = testfunction(**testargs)
E       TypeError: TestSummaryFunctions.test_count_words() takes 0 positional arguments but 1 was given

.venv/lib/python3.12/site-packages/_pytest/python.py:194: TypeError
=============================== warnings summary ===============================
.venv/lib/python3.12/site-packages/sqlalchemy/sql/sqltypes.py:2061
  /home/kasper/Programming/mediaocean-cc/backend/.venv/lib/python3.12/site-packages/sqlalchemy/sql/sqltypes.py:2061: DeprecationWarning: datetime.datetime.utcfromtimestamp() is deprecated and scheduled for removal in a future version. Use timezone-aware objects to represent datetimes in UTC: datetime.datetime.fromtimestamp(timestamp, datetime.UTC).
    epoch = dt.datetime.utcfromtimestamp(0)

-- Docs: https://docs.pytest.org/en/stable/how-to/capture-warnings.html
=========================== short test summary info ============================
FAILED tests/test_summary.py::TestSummaryFunctions::test_count_words - TypeEr...
========================= 1 failed, 1 warning in 0.45s =========================
